I'm sorry, but an uncaught exception occurred.

While running game code:
  File "game/chapter6.rpy", line 10, in script
    c1 "Welcome to chapter 6."
Exception: Sayer 'c1' is not defined.

-- Full Traceback ------------------------------------------------------------

Full traceback:
  File "game/chapter6.rpy", line 10, in script
    c1 "Welcome to chapter 6."
  File "C:\Users\Pheon\Desktop\renpy-7.3.5-sdk\renpy\ast.py", line 678, in execute
    who = eval_who(self.who, self.who_fast)
  File "C:\Users\Pheon\Desktop\renpy-7.3.5-sdk\renpy\ast.py", line 576, in eval_who
    raise Exception("Sayer '%s' is not defined." % who.encode("utf-8"))
Exception: Sayer 'c1' is not defined.

Windows-8-6.2.9200
Ren'Py 7.3.5.606
Call of the Truth 1.0
Tue Jun 02 00:32:07 2020
